Workbook

Sheet DASHBOARD
A1: SUBU PERSONAL FINANCE & PORTFOLIO — MASTER DASHBOARD
A2: 📅 SELECT PERIOD: | D2: All Time | H2: =IF(D2="Last Month","Period: "& TEXT(EOMONTH(TODAY(),-2)+1,"MMM-YY")&" to "&TEXT(EOMONTH(TODAY(),-1),"MMM-YY"),IF(D2="Last 3 Months","Period: "&TEXT(EOMONTH(TODAY(),-3)+1,"MMM-YY")&" to "&TEXT(TODAY(),"MMM-YY"),IF(D2="Last 6 Months","Period: "&TEXT(EOMONTH(TODAY(),-6)+1,"MMM-YY")&" to "&TEXT(TODAY(),"MMM-YY"),IF(D2="Last 12 Months","Period: "&TEXT(EOMONTH(TODAY(),-12)+1,"MMM-YY")&" to "&TEXT(TODAY(),"MMM-YY"),IF(D2="Year to Date","Period: Jan-"&YEAR(TODAY())&" to "&TEXT(TODAY(),"MMM-YY"),"All Time: Feb-2025 to Today"))))) -> All Time: Feb-2025 to Today | P2: =IF(D2="Last Month",EOMONTH(TODAY(),-2)+1,IF(D2="Last 3 Months",EOMONTH(TODAY(),-3)+1,IF(D2="Last 6 Months",EOMONTH(TODAY(),-6)+1,IF(D2="Last 12 Months",EOMONTH(TODAY(),-12)+1,IF(D2="Year to Date",DATE(YEAR(TODAY()),1,1),DATE(2025,2,1)))))) -> 45689 | Q2: =IF(D2="Last Month",EOMONTH(TODAY(),-1),TODAY()) -> 46277
A4: 💰 TOTAL WEALTH | E4: 📥 PERIOD INCOME | I4: 📤 PERIOD EXPENSES | M4: 💸 NET SAVINGS
A5: =SUMIF('IN-HAND'!D:D,"Personal SBI (Saving)",'IN-HAND'!C:C)+SUMIF('IN-HAND'!D:D,"SBI FD",'IN-HAND'!C:C)+SUMIF('IN-HAND'!D:D,"EPFO",'IN-HAND'!C:C)+PORTFOLIO!E5 -> 391443.83 | E5: =IFERROR(SUMPRODUCT((INCOME!A$4:A$501>=$P$2)*(INCOME!A$4:A$501<=$Q$2)*(INCOME!C$4:C$501>0)*(INCOME!D$4:D$501<>"Expense Money")*INCOME!C$4:C$501),0) -> 113748 | I5: =IFERROR(SUMPRODUCT((EXPENSES!A$4:A$1999>=$P$2)*(EXPENSES!A$4:A$1999<=$Q$2)*EXPENSES!D$4:D$1999),0) -> 84425.18 | M5: =IFERROR(SUMPRODUCT((INCOME!A$4:A$501>=$P$2)*(INCOME!A$4:A$501<=$Q$2)*(INCOME!C$4:C$501>0)*(INCOME!D$4:D$501<>"Expense Money")*INCOME!C$4:C$501)-SUMPRODUCT((EXPENSES!A$4:A$1999>=$P$2)*(EXPENSES!A$4:A$1999<=$Q$2)*EXPENSES!D$4:D$1999),0) -> 29322.82
A6: Total across all assets | E6: Real income (excl. transfers) | I6: Total spending in period | M6: Income minus Expenses
A8: 🏦 BANK BALANCE | E8: 🔒 FD | I8: 🪙 CRYPTO VALUE | M8: 📊 SHARES VALUE
A9: =SUMIF('IN-HAND'!D:D,"Personal SBI (Saving)",'IN-HAND'!C:C) -> 117580.84 | E9: =SUMIF('IN-HAND'!D:D,"SBI FD",'IN-HAND'!C:C)+SUMIF('IN-HAND'!D:D,"EPFO",'IN-HAND'!C:C) -> 150000 | I9: =PORTFOLIO!E3 -> 95178.614 | M9: =PORTFOLIO!E4 -> 28684.381
A10: Personal SBI Savings Account | E10: Fixed Deposits & Provident Fund | I10: Live crypto holdings value | M10: Mutual funds & ETF value
A12: 📊 EXPENSE BREAKDOWN BY CATEGORY — Period selected above
R13: Category | S13: Amount
R14: Bills & Utilities | S14: =IFERROR(SUMPRODUCT((EXPENSES!A$4:A$1999>=$P$2)*(EXPENSES!A$4:A$1999<=$Q$2)*(EXPENSES!E$4:E$1999="Bills & Utilities")*EXPENSES!D$4:D$1999),0) -> 6689
B15: Your Actual Data of Income | R15: Childcare & Baby Needs | S15: =IFERROR(SUMPRODUCT((EXPENSES!A$4:A$1999>=$P$2)*(EXPENSES!A$4:A$1999<=$Q$2)*(EXPENSES!E$4:E$1999="Childcare & Baby Needs")*EXPENSES!D$4:D$1999),0) -> 0
B16: 🏦 BANK BALANCE | C16: =A9 -> 117580.84 | D16: =C16/$C$20 -> 0.30037729 | R16: Education | S16: =IFERROR(SUMPRODUCT((EXPENSES!A$4:A$1999>=$P$2)*(EXPENSES!A$4:A$1999<=$Q$2)*(EXPENSES!E$4:E$1999="Education")*EXPENSES!D$4:D$1999),0) -> 3088
B17: 🔒 FD | C17: =E9 -> 150000 | D17: =C17/$C$20 -> 0.38319674 | R17: Electronics & Gadgets | S17: =IFERROR(SUMPRODUCT((EXPENSES!A$4:A$1999>=$P$2)*(EXPENSES!A$4:A$1999<=$Q$2)*(EXPENSES!E$4:E$1999="Electronics & Gadgets")*EXPENSES!D$4:D$1999),0) -> 1614
B18: 🪙 CRYPTO VALUE | C18: =I9 -> 95178.614 | D18: =C18/$C$20 -> 0.24314756 | R18: Entertainment | S18: =IFERROR(SUMPRODUCT((EXPENSES!A$4:A$1999>=$P$2)*(EXPENSES!A$4:A$1999<=$Q$2)*(EXPENSES!E$4:E$1999="Entertainment")*EXPENSES!D$4:D$1999),0) -> 0
B19: 📊 Shares & Commodities | C19: =M9 -> 28684.381 | D19: =C19/$C$20 -> 0.073278407 | R19: Familly | S19: =IFERROR(SUMPRODUCT((EXPENSES!A$4:A$1999>=$P$2)*(EXPENSES!A$4:A$1999<=$Q$2)*(EXPENSES!E$4:E$1999="Familly")*EXPENSES!D$4:D$1999),0) -> 0
B20: 💰 TOTAL WEALTH | C20: =SUM(C16:C19) -> 391443.83 | D20: =C20/$C$20 -> 1 | R20: Fitness | S20: =IFERROR(SUMPRODUCT((EXPENSES!A$4:A$1999>=$P$2)*(EXPENSES!A$4:A$1999<=$Q$2)*(EXPENSES!E$4:E$1999="Fitness")*EXPENSES!D$4:D$1999),0) -> 0
R21: Snacks & Quick Bites | S21: =IFERROR(SUMPRODUCT((EXPENSES!A$4:A$1999>=$P$2)*(EXPENSES!A$4:A$1999<=$Q$2)*(EXPENSES!E$4:E$1999="Snacks & Quick Bites")*EXPENSES!D$4:D$1999),0) -> 3496
R22: Fuel | S22: =IFERROR(SUMPRODUCT((EXPENSES!A$4:A$1999>=$P$2)*(EXPENSES!A$4:A$1999<=$Q$2)*(EXPENSES!E$4:E$1999="Fuel")*EXPENSES!D$4:D$1999),0) -> 641
R23: Gifts | S23: =IFERROR(SUMPRODUCT((EXPENSES!A$4:A$1999>=$P$2)*(EXPENSES!A$4:A$1999<=$Q$2)*(EXPENSES!E$4:E$1999="Gifts")*EXPENSES!D$4:D$1999),0) -> 21760
R24: Groceries | S24: =IFERROR(SUMPRODUCT((EXPENSES!A$4:A$1999>=$P$2)*(EXPENSES!A$4:A$1999<=$Q$2)*(EXPENSES!E$4:E$1999="Groceries")*EXPENSES!D$4:D$1999),0) -> 3607
R25: HouseHold | S25: =IFERROR(SUMPRODUCT((EXPENSES!A$4:A$1999>=$P$2)*(EXPENSES!A$4:A$1999<=$Q$2)*(EXPENSES!E$4:E$1999="HouseHold")*EXPENSES!D$4:D$1999),0) -> 285
R26: Insurance | S26: =IFERROR(SUMPRODUCT((EXPENSES!A$4:A$1999>=$P$2)*(EXPENSES!A$4:A$1999<=$Q$2)*(EXPENSES!E$4:E$1999="Insurance")*EXPENSES!D$4:D$1999),0) -> 0
R27: Investments | S27: =IFERROR(SUMPRODUCT((EXPENSES!A$4:A$1999>=$P$2)*(EXPENSES!A$4:A$1999<=$Q$2)*(EXPENSES!E$4:E$1999="Investments")*EXPENSES!D$4:D$1999),0) -> 14000
R28: Loans Given & Taken | S28: =IFERROR(SUMPRODUCT((EXPENSES!A$4:A$1999>=$P$2)*(EXPENSES!A$4:A$1999<=$Q$2)*(EXPENSES!E$4:E$1999="Loans Given & Taken")*EXPENSES!D$4:D$1999),0) -> 7800
R29: Medical | S29: =IFERROR(SUMPRODUCT((EXPENSES!A$4:A$1999>=$P$2)*(EXPENSES!A$4:A$1999<=$Q$2)*(EXPENSES!E$4:E$1999="Medical")*EXPENSES!D$4:D$1999),0) -> 1367
R30: Personal Care | S30: =IFERROR(SUMPRODUCT((EXPENSES!A$4:A$1999>=$P$2)*(EXPENSES!A$4:A$1999<=$Q$2)*(EXPENSES!E$4:E$1999="Personal Care")*EXPENSES!D$4:D$1999),0) -> 1433
R31: Rent | S31: =IFERROR(SUMPRODUCT((EXPENSES!A$4:A$1999>=$P$2)*(EXPENSES!A$4:A$1999<=$Q$2)*(EXPENSES!E$4:E$1999="Rent")*EXPENSES!D$4:D$1999),0) -> 0

Sheet EXPENSES
A1: 📤 EXPENSE TRACKER — Add rows below to record spending
A2: Type | B2: Auto | C2: Type | D2: Type | E2: Select | F2: Auto | G2: Type
A3: Date | B3: Month | C3: Store / Vendor | D3: Amount (₹) | E3: Category | F3: Expense Keys / Tags | G3: Notes
A4: 45717 | B4: =IFERROR(IF(A4<=0,"",TEXT(A4,"MMM YY")),"") -> Mar 25 | C4: Kings Restaurant LLP | D4: 208 | E4: Restaurant & Dining Out | F4: =IFERROR(VLOOKUP(E4,SETTINGS!A:B,2,0),"No Value") -> Dining Out, Fast Food, Café, Home Delivery, Street Food
A5: 45717 | B5: =IFERROR(IF(A5<=0,"",TEXT(A5,"MMM YY")),"") -> Mar 25 | C5: Lobh Petrolleum | D5: 641 | E5: Fuel | F5: =IFERROR(VLOOKUP(E5,SETTINGS!A:B,2,0),"No Value") -> Petrol, Diesel, CNG, Electric Charging Stations
A6: 45717 | B6: =IFERROR(IF(A6<=0,"",TEXT(A6,"MMM YY")),"") -> Mar 25 | C6: Jyotirlinga Vadapaav Center | D6: 77 | E6: Snacks & Quick Bites | F6: =IFERROR(VLOOKUP(E6,SETTINGS!A:B,2,0),"No Value") -> Office tea/coffee, Small breaks, Bakery items, Juice, chips, biscuits
A7: 45718 | B7: =IFERROR(IF(A7<=0,"",TEXT(A7,"MMM YY")),"") -> Mar 25 | C7: Mr. PavanKumar Pardesi | D7: 200 | E7: Gifts | F7: =IFERROR(VLOOKUP(E7,SETTINGS!A:B,2,0),"No Value") -> Birthday Gifts, Anniversary Gifts, Festival Gifts, Wedding Gifts, Gifts for Friends
A8: 45718 | B8: =IFERROR(IF(A8<=0,"",TEXT(A8,"MMM YY")),"") -> Mar 25 | C8: Bhagwan Pandurang Shinde | D8: 100 | E8: Personal Care | F8: =IFERROR(VLOOKUP(E8,SETTINGS!A:B,2,0),"No Value") -> Haircuts, Skincare, Beauty Products, Grooming Kits, Salon
A9: 45720 | B9: =IFERROR(IF(A9<=0,"",TEXT(A9,"MMM YY")),"") -> Mar 25 | C9: lending from Sis | D9: 1000 | E9: Loans Given & Taken | F9: =IFERROR(VLOOKUP(E9,SETTINGS!A:B,2,0),"No Value") -> Borrowing from Friends, Lending to Family, Interest on Loan
A10: 45720 | B10: =IFERROR(IF(A10<=0,"",TEXT(A10,"MMM YY")),"") -> Mar 25 | C10: Office Trip | D10: 146 | E10: Travel | F10: =IFERROR(VLOOKUP(E10,SETTINGS!A:B,2,0),"No Value") -> Flight Tickets, Hotel Stays, Sightseeing, Rental Cars, Visa Fees
A11: 45720 | B11: =IFERROR(IF(A11<=0,"",TEXT(A11,"MMM YY")),"") -> Mar 25 | C11: Pickle | D11: 200 | E11: Snacks & Quick Bites | F11: =IFERROR(VLOOKUP(E11,SETTINGS!A:B,2,0),"No Value") -> Office tea/coffee, Small breaks, Bakery items, Juice, chips, biscuits
A12: 45723 | B12: =IFERROR(IF(A12<=0,"",TEXT(A12,"MMM YY")),"") -> Mar 25 | C12: Plus Point Medico | D12: 10 | E12: Medical | F12: =IFERROR(VLOOKUP(E12,SETTINGS!A:B,2,0),"No Value") -> Medicines, Doctor Consultation, Hospitalization, Surgery
A13: 45724 | B13: =IFERROR(IF(A13<=0,"",TEXT(A13,"MMM YY")),"") -> Mar 25 | C13: Hotel Sai Park Satara | D13: 130 | E13: Restaurant & Dining Out | F13: =IFERROR(VLOOKUP(E13,SETTINGS!A:B,2,0),"No Value") -> Dining Out, Fast Food, Café, Home Delivery, Street Food
A14: 45724 | B14: =IFERROR(IF(A14<=0,"",TEXT(A14,"MMM YY")),"") -> Mar 25 | C14: vikas shankar | D14: 140 | E14: Restaurant & Dining Out | F14: =IFERROR(VLOOKUP(E14,SETTINGS!A:B,2,0),"No Value") -> Dining Out, Fast Food, Café, Home Delivery, Street Food
A15: 45725 | B15: =IFERROR(IF(A15<=0,"",TEXT(A15,"MMM YY")),"") -> Mar 25 | C15: mr takhat singh raj | D15: 240 | E15: Gifts | F15: =IFERROR(VLOOKUP(E15,SETTINGS!A:B,2,0),"No Value") -> Birthday Gifts, Anniversary Gifts, Festival Gifts, Wedding Gifts, Gifts for Friends
... A159: 45865 | B159: =IFERROR(IF(A159<=0,"",TEXT(A159,"MMM YY")),"") -> Jul 25 | C159: Office FareWeel Contri | D159: 200 | E159: Gifts | F159: =IFERROR(VLOOKUP(E159,SETTINGS!A:B,2,0),"No Value") -> Birthday Gifts, Anniversary Gifts, Festival Gifts, Wedding Gifts, Gifts for Friends
B160: =IFERROR(IF(A591<=0,"",TEXT(A591,"MMM YY")),"") | F160: =IFERROR(VLOOKUP(E591,SETTINGS!A:B,2,0),"No Value") -> No Value
B161: =IFERROR(IF(A592<=0,"",TEXT(A592,"MMM YY")),"") | F161: =IFERROR(VLOOKUP(E592,SETTINGS!A:B,2,0),"No Value") -> No Value
B162: =IFERROR(IF(A593<=0,"",TEXT(A593,"MMM YY")),"") | F162: =IFERROR(VLOOKUP(E593,SETTINGS!A:B,2,0),"No Value") -> No Value
B163: =IFERROR(IF(A594<=0,"",TEXT(A594,"MMM YY")),"") | F163: =IFERROR(VLOOKUP(E594,SETTINGS!A:B,2,0),"No Value") -> No Value
B164: =IFERROR(IF(A595<=0,"",TEXT(A595,"MMM YY")),"") | F164: =IFERROR(VLOOKUP(E595,SETTINGS!A:B,2,0),"No Value") -> No Value
B165: =IFERROR(IF(A596<=0,"",TEXT(A596,"MMM YY")),"") | F165: =IFERROR(VLOOKUP(E596,SETTINGS!A:B,2,0),"No Value") -> No Value
B166: =IFERROR(IF(A597<=0,"",TEXT(A597,"MMM YY")),"") | F166: =IFERROR(VLOOKUP(E597,SETTINGS!A:B,2,0),"No Value") -> No Value
B167: =IFERROR(IF(A598<=0,"",TEXT(A598,"MMM YY")),"") | F167: =IFERROR(VLOOKUP(E598,SETTINGS!A:B,2,0),"No Value") -> No Value
B168: =IFERROR(IF(A599<=0,"",TEXT(A599,"MMM YY")),"") | F168: =IFERROR(VLOOKUP(E599,SETTINGS!A:B,2,0),"No Value") -> No Value
B169: =IFERROR(IF(A600<=0,"",TEXT(A600,"MMM YY")),"") | F169: =IFERROR(VLOOKUP(E600,SETTINGS!A:B,2,0),"No Value") -> No Value
B170: =IFERROR(IF(A601<=0,"",TEXT(A601,"MMM YY")),"") | F170: =IFERROR(VLOOKUP(E601,SETTINGS!A:B,2,0),"No Value") -> No Value
B171: =IFERROR(IF(A602<=0,"",TEXT(A602,"MMM YY")),"") | F171: =IFERROR(VLOOKUP(E602,SETTINGS!A:B,2,0),"No Value") -> No Value
... B568: =IFERROR(IF(A999<=0,"",TEXT(A999,"MMM YY")),"") | F568: =IFERROR(VLOOKUP(E999,SETTINGS!A:B,2,0),"No Value") -> No Value

Sheet INCOME
A1: 💰 INCOME TRACKER — Salary, Side Income, Returns
A2: Type | B2: Type | C2: Type | D2: Select | E2: Type
A3: Date | B3: Source | C3: Amount (₹) | D3: Category | E3: Notes
A4: 45689 | B4: Ondirect Company Salary | C4: 0 | D4: Job / Salary
A5: 45717 | B5: Ondirect Company Salary | C5: 21929 | D5: Job / Salary
A6: 45717 | B6: Trasfer to Expenses accounts | C6: -7000 | D6: Job / Salary
A7: 45717 | B7: Expenses money Transfer | C7: 7000 | D7: Expense Money
A8: 45748 | B8: Ondirect Company Salary | C8: 22029 | D8: Job / Salary
A9: 45748 | B9: Trasfer to Expenses accounts | C9: -8000 | D9: Job / Salary
A10: 45748 | B10: Expenses money Transfer | C10: 8000 | D10: Expense Money
A11: 45778 | B11: Ondirect Company Salary | C11: 22029 | D11: Job / Salary
A12: 45778 | B12: Trasfer to Expenses accounts | C12: -11014 | D12: Job / Salary
A13: 45778 | B13: Expenses Money Transfer | C13: 11014 | D13: Expense Money
A14: 45793 | B14: College Project Work | C14: 2000 | D14: Side Income
A15: 45795 | B15: College Project Work | C15: 2000 | D15: Side Income
... A21: 45839 | B21: Expenses Money Transfer | C21: 11589 | D21: Expense Money

Sheet IN-HAND
A1: 🏦 IN-HAND BALANCE TRACKER — Bank, FD, EPFO
A2: Type | B2: Type | C2: Type | D2: Select | E2: Type
A3: Date | B3: Source / Account | C3: Amount (₹) | D3: Account Type | E3: Notes | G3: BALANCE SUMMARY
A4: 45716 | B4: Personal SBI Account | C4: 61682.97 | D4: Personal SBI (Saving)
A5: 45716 | B5: SBI FD | C5: 150000 | D5: SBI FD | G5: Personal SBI | H5: =SUMIF(D:D,"Personal SBI (Saving)",C:C) -> 117580.84
A6: 45717 | B6: Ondirect Company Salary | C6: 14929 | D6: Personal SBI (Saving) | G6: SBI FD | H6: =SUMIF(D:D,"SBI FD",C:C) -> 150000
A7: 45748 | B7: Ondirect Company Salary | C7: 14029 | D7: Personal SBI (Saving) | G7: EPFO | H7: =SUMIF(D:D,"EPFO",C:C) -> 0
A8: 45748 | B8: SBI INTEREST EARN | C8: 337.87 | D8: Personal SBI (Saving) | G8: TOTAL IN-HAND | H8: =SUMIF(D:D,"Personal SBI (Saving)",C:C)+SUMIF(D:D,"SBI FD",C:C)+SUMIF(D:D,"EPFO",C:C) -> 267580.84
A9: 45776 | B9: Withdraw Peronal SBI Account | C9: -20000 | D9: Personal SBI (Saving)
A10: 45778 | B10: Ondirect Company Salary | C10: 11015 | D10: Personal SBI (Saving)
A11: 45795 | B11: Mangesh Ghadge | C11: 15000 | D11: Personal SBI (Saving)
A12: 45809 | B12: Ondirect Company Salary | C12: 12223 | D12: Personal SBI (Saving)
A13: 45839 | B13: Ondirect Company Salary | C13: 7726 | D13: Personal SBI (Saving)
A14: 45839 | B14: SBI INTEREST EARN | C14: 638 | D14: Personal SBI (Saving)

Sheet BUDGET TRACKER
A1: 📊 BUDGET TRACKER — Total Actuals + Category Comparison
A2: 📈 YOUR ACTUAL SPENDING + BUDGET TARGETS | J2: 🎯 COMPARISON — SELECT PERIOD & COMPARE vs BUDGET
J3: Start Date: | K3: 45809 | L3: End Date: | M3: 45833
A4: # | B4: Expense Category | C4: Monthly Average | D4: Total — All Time | E4: % of Total | G4: Monthly Budget Rs | H4: Implied Annual Rs | J4: # | K4: Expense Category | L4: Actual Expenses | M4: Budget Target | N4: Variance (₹) | O4: Variance (%)
A5: 1 | B5: =SETTINGS!A3 -> Bills & Utilities | C5: =IFERROR(SUMPRODUCT((EXPENSES!E$4:E$1999=B5)*EXPENSES!D$4:D$1999)/MAX(COUNTIF(EXPENSES!D$4:D$1999,">0"),1),0) -> 42.878205 | D5: =IFERROR(SUMPRODUCT((EXPENSES!E$4:E$1999=B5)*EXPENSES!D$4:D$1999),0) -> 6689 | E5: =IFERROR(D5/SUM(D$5:D$34),0) -> 0.079229917 | G5: 0 | H5: =G5*12 -> 0 | J5: 1 | K5: =SETTINGS!A3 -> Bills & Utilities | L5: =IFERROR(SUMPRODUCT((EXPENSES!A$4:A$1999>=$K$3)*(EXPENSES!A$4:A$1999<=$M$3)*(EXPENSES!E$4:E$1999=K5)*EXPENSES!D$4:D$1999),0) -> 1599 | M5: =H5/12 -> 0 | N5: =L5-M5 -> 1599 | O5: =IFERROR(N5/M5,0) -> 0
A6: 2 | B6: =SETTINGS!A4 -> Childcare & Baby Needs | C6: =IFERROR(SUMPRODUCT((EXPENSES!E$4:E$1999=B6)*EXPENSES!D$4:D$1999)/MAX(COUNTIF(EXPENSES!D$4:D$1999,">0"),1),0) -> 0 | D6: =IFERROR(SUMPRODUCT((EXPENSES!E$4:E$1999=B6)*EXPENSES!D$4:D$1999),0) -> 0 | E6: =IFERROR(D6/SUM(D$5:D$34),0) -> 0 | G6: 0 | H6: =G6*12 -> 0 | J6: 2 | K6: =SETTINGS!A4 -> Childcare & Baby Needs | L6: =IFERROR(SUMPRODUCT((EXPENSES!A$4:A$1999>=$K$3)*(EXPENSES!A$4:A$1999<=$M$3)*(EXPENSES!E$4:E$1999=K6)*EXPENSES!D$4:D$1999),0) -> 0 | M6: =H6/12 -> 0 | N6: =L6-M6 -> 0 | O6: =IFERROR(N6/M6,0) -> 0
A7: 3 | B7: =SETTINGS!A5 -> Commute | C7: =IFERROR(SUMPRODUCT((EXPENSES!E$4:E$1999=B7)*EXPENSES!D$4:D$1999)/MAX(COUNTIF(EXPENSES!D$4:D$1999,">0"),1),0) -> 4.7435897 | D7: =IFERROR(SUMPRODUCT((EXPENSES!E$4:E$1999=B7)*EXPENSES!D$4:D$1999),0) -> 740 | E7: =IFERROR(D7/SUM(D$5:D$34),0) -> 0.0087651575 | G7: 0 | H7: =G7*12 -> 0 | J7: 3 | K7: =SETTINGS!A5 -> Commute | L7: =IFERROR(SUMPRODUCT((EXPENSES!A$4:A$1999>=$K$3)*(EXPENSES!A$4:A$1999<=$M$3)*(EXPENSES!E$4:E$1999=K7)*EXPENSES!D$4:D$1999),0) -> 0 | M7: =H7/12 -> 0 | N7: =L7-M7 -> 0 | O7: =IFERROR(N7/M7,0) -> 0
A8: 4 | B8: =SETTINGS!A6 -> Education | C8: =IFERROR(SUMPRODUCT((EXPENSES!E$4:E$1999=B8)*EXPENSES!D$4:D$1999)/MAX(COUNTIF(EXPENSES!D$4:D$1999,">0"),1),0) -> 19.794872 | D8: =IFERROR(SUMPRODUCT((EXPENSES!E$4:E$1999=B8)*EXPENSES!D$4:D$1999),0) -> 3088 | E8: =IFERROR(D8/SUM(D$5:D$34),0) -> 0.036576765 | G8: 0 | H8: =G8*12 -> 0 | J8: 4 | K8: =SETTINGS!A6 -> Education | L8: =IFERROR(SUMPRODUCT((EXPENSES!A$4:A$1999>=$K$3)*(EXPENSES!A$4:A$1999<=$M$3)*(EXPENSES!E$4:E$1999=K8)*EXPENSES!D$4:D$1999),0) -> 80 | M8: =H8/12 -> 0 | N8: =L8-M8 -> 80 | O8: =IFERROR(N8/M8,0) -> 0
A9: 5 | B9: =SETTINGS!A7 -> Electronics & Gadgets | C9: =IFERROR(SUMPRODUCT((EXPENSES!E$4:E$1999=B9)*EXPENSES!D$4:D$1999)/MAX(COUNTIF(EXPENSES!D$4:D$1999,">0"),1),0) -> 10.346154 | D9: =IFERROR(SUMPRODUCT((EXPENSES!E$4:E$1999=B9)*EXPENSES!D$4:D$1999),0) -> 1614 | E9: =IFERROR(D9/SUM(D$5:D$34),0) -> 0.019117519 | G9: 0 | H9: =G9*12 -> 0 | J9: 5 | K9: =SETTINGS!A7 -> Electronics & Gadgets | L9: =IFERROR(SUMPRODUCT((EXPENSES!A$4:A$1999>=$K$3)*(EXPENSES!A$4:A$1999<=$M$3)*(EXPENSES!E$4:E$1999=K9)*EXPENSES!D$4:D$1999),0) -> 0 | M9: =H9/12 -> 0 | N9: =L9-M9 -> 0 | O9: =IFERROR(N9/M9,0) -> 0
A10: 6 | B10: =SETTINGS!A8 -> Entertainment | C10: =IFERROR(SUMPRODUCT((EXPENSES!E$4:E$1999=B10)*EXPENSES!D$4:D$1999)/MAX(COUNTIF(EXPENSES!D$4:D$1999,">0"),1),0) -> 0 | D10: =IFERROR(SUMPRODUCT((EXPENSES!E$4:E$1999=B10)*EXPENSES!D$4:D$1999),0) -> 0 | E10: =IFERROR(D10/SUM(D$5:D$34),0) -> 0 | G10: 0 | H10: =G10*12 -> 0 | J10: 6 | K10: =SETTINGS!A8 -> Entertainment | L10: =IFERROR(SUMPRODUCT((EXPENSES!A$4:A$1999>=$K$3)*(EXPENSES!A$4:A$1999<=$M$3)*(EXPENSES!E$4:E$1999=K10)*EXPENSES!D$4:D$1999),0) -> 0 | M10: =H10/12 -> 0 | N10: =L10-M10 -> 0 | O10: =IFERROR(N10/M10,0) -> 0
A11: 7 | B11: =SETTINGS!A9 -> Familly | C11: =IFERROR(SUMPRODUCT((EXPENSES!E$4:E$1999=B11)*EXPENSES!D$4:D$1999)/MAX(COUNTIF(EXPENSES!D$4:D$1999,">0"),1),0) -> 0 | D11: =IFERROR(SUMPRODUCT((EXPENSES!E$4:E$1999=B11)*EXPENSES!D$4:D$1999),0) -> 0 | E11: =IFERROR(D11/SUM(D$5:D$34),0) -> 0 | G11: 0 | H11: =G11*12 -> 0 | J11: 7 | K11: =SETTINGS!A9 -> Familly | L11: =IFERROR(SUMPRODUCT((EXPENSES!A$4:A$1999>=$K$3)*(EXPENSES!A$4:A$1999<=$M$3)*(EXPENSES!E$4:E$1999=K11)*EXPENSES!D$4:D$1999),0) -> 0 | M11: =H11/12 -> 0 | N11: =L11-M11 -> 0 | O11: =IFERROR(N11/M11,0) -> 0
A12: 8 | B12: =SETTINGS!A10 -> Fitness | C12: =IFERROR(SUMPRODUCT((EXPENSES!E$4:E$1999=B12)*EXPENSES!D$4:D$1999)/MAX(COUNTIF(EXPENSES!D$4:D$1999,">0"),1),0) -> 0 | D12: =IFERROR(SUMPRODUCT((EXPENSES!E$4:E$1999=B12)*EXPENSES!D$4:D$1999),0) -> 0 | E12: =IFERROR(D12/SUM(D$5:D$34),0) -> 0 | G12: 0 | H12: =G12*12 -> 0 | J12: 8 | K12: =SETTINGS!A10 -> Fitness | L12: =IFERROR(SUMPRODUCT((EXPENSES!A$4:A$1999>=$K$3)*(EXPENSES!A$4:A$1999<=$M$3)*(EXPENSES!E$4:E$1999=K12)*EXPENSES!D$4:D$1999),0) -> 0 | M12: =H12/12 -> 0 | N12: =L12-M12 -> 0 | O12: =IFERROR(N12/M12,0) -> 0
A13: 9 | B13: =SETTINGS!A11 -> Snacks & Quick Bites | C13: =IFERROR(SUMPRODUCT((EXPENSES!E$4:E$1999=B13)*EXPENSES!D$4:D$1999)/MAX(COUNTIF(EXPENSES!D$4:D$1999,">0"),1),0) -> 22.410256 | D13: =IFERROR(SUMPRODUCT((EXPENSES!E$4:E$1999=B13)*EXPENSES!D$4:D$1999),0) -> 3496 | E13: =IFERROR(D13/SUM(D$5:D$34),0) -> 0.041409447 | G13: 0 | H13: =G13*12 -> 0 | J13: 9 | K13: =SETTINGS!A11 -> Snacks & Quick Bites | L13: =IFERROR(SUMPRODUCT((EXPENSES!A$4:A$1999>=$K$3)*(EXPENSES!A$4:A$1999<=$M$3)*(EXPENSES!E$4:E$1999=K13)*EXPENSES!D$4:D$1999),0) -> 951 | M13: =H13/12 -> 0 | N13: =L13-M13 -> 951 | O13: =IFERROR(N13/M13,0) -> 0
A14: 10 | B14: =SETTINGS!A12 -> Fuel | C14: =IFERROR(SUMPRODUCT((EXPENSES!E$4:E$1999=B14)*EXPENSES!D$4:D$1999)/MAX(COUNTIF(EXPENSES!D$4:D$1999,">0"),1),0) -> 4.1089744 | D14: =IFERROR(SUMPRODUCT((EXPENSES!E$4:E$1999=B14)*EXPENSES!D$4:D$1999),0) -> 641 | E14: =IFERROR(D14/SUM(D$5:D$34),0) -> 0.0075925216 | G14: 0 | H14: =G14*12 -> 0 | J14: 10 | K14: =SETTINGS!A12 -> Fuel | L14: =IFERROR(SUMPRODUCT((EXPENSES!A$4:A$1999>=$K$3)*(EXPENSES!A$4:A$1999<=$M$3)*(EXPENSES!E$4:E$1999=K14)*EXPENSES!D$4:D$1999),0) -> 0 | M14: =H14/12 -> 0 | N14: =L14-M14 -> 0 | O14: =IFERROR(N14/M14,0) -> 0
A15: 11 | B15: =SETTINGS!A13 -> Gifts | C15: =IFERROR(SUMPRODUCT((EXPENSES!E$4:E$1999=B15)*EXPENSES!D$4:D$1999)/MAX(COUNTIF(EXPENSES!D$4:D$1999,">0"),1),0) -> 139.48718 | D15: =IFERROR(SUMPRODUCT((EXPENSES!E$4:E$1999=B15)*EXPENSES!D$4:D$1999),0) -> 21760 | E15: =IFERROR(D15/SUM(D$5:D$34),0) -> 0.25774301 | G15: 0 | H15: =G15*12 -> 0 | J15: 11 | K15: =SETTINGS!A13 -> Gifts | L15: =IFERROR(SUMPRODUCT((EXPENSES!A$4:A$1999>=$K$3)*(EXPENSES!A$4:A$1999<=$M$3)*(EXPENSES!E$4:E$1999=K15)*EXPENSES!D$4:D$1999),0) -> 0 | M15: =H15/12 -> 0 | N15: =L15-M15 -> 0 | O15: =IFERROR(N15/M15,0) -> 0
A16: 12 | B16: =SETTINGS!A14 -> Groceries | C16: =IFERROR(SUMPRODUCT((EXPENSES!E$4:E$1999=B16)*EXPENSES!D$4:D$1999)/MAX(COUNTIF(EXPENSES!D$4:D$1999,">0"),1),0) -> 23.121795 | D16: =IFERROR(SUMPRODUCT((EXPENSES!E$4:E$1999=B16)*EXPENSES!D$4:D$1999),0) -> 3607 | E16: =IFERROR(D16/SUM(D$5:D$34),0) -> 0.04272422 | G16: 0 | H16: =G16*12 -> 0 | J16: 12 | K16: =SETTINGS!A14 -> Groceries | L16: =IFERROR(SUMPRODUCT((EXPENSES!A$4:A$1999>=$K$3)*(EXPENSES!A$4:A$1999<=$M$3)*(EXPENSES!E$4:E$1999=K16)*EXPENSES!D$4:D$1999),0) -> 834 | M16: =H16/12 -> 0 | N16: =L16-M16 -> 834 | O16: =IFERROR(N16/M16,0) -> 0
... A34: 30 | B34: =SETTINGS!A32 | C34: =IFERROR(SUMPRODUCT((EXPENSES!E$4:E$1999=B34)*EXPENSES!D$4:D$1999)/MAX(COUNTIF(EXPENSES!D$4:D$1999,">0"),1),0) -> 0 | D34: =IFERROR(SUMPRODUCT((EXPENSES!E$4:E$1999=B34)*EXPENSES!D$4:D$1999),0) -> 0 | E34: =IFERROR(D34/SUM(D$5:D$34),0) -> 0 | G34: 0 | H34: =G34*12 -> 0 | J34: 30 | K34: =SETTINGS!A32 | L34: =IFERROR(SUMPRODUCT((EXPENSES!A$4:A$1999>=$K$3)*(EXPENSES!A$4:A$1999<=$M$3)*(EXPENSES!E$4:E$1999=K34)*EXPENSES!D$4:D$1999),0) -> 0 | M34: =H34/12 -> 0 | N34: =L34-M34 -> 0 | O34: =IFERROR(N34/M34,0) -> 0
A35: TOTALS | C35: =SUM(C5:C34) -> 541.18705 | D35: =SUM(D5:D34) -> 84425.18 | E35: =SUM(E5:E34) -> 1 | G35: =SUM(G5:G34) -> 0 | H35: =SUM(H5:H34) -> 0 | J35: PERIOD TOTAL | L35: =SUM(L5:L34) -> 13634.6 | M35: =SUM(M5:M34) -> 0 | N35: =SUM(N5:N34) -> 13634.6 | O35: =SUM(O5:O34) -> 0
A36: TOTALS WithOut Investment | C36: =SUM(C5:C18,C20:C34) -> 451.44346 | D36: =SUM(D5:D18,D20:D34) -> 70425.18 | E36: =SUM(E5:E18,E20:E34) -> 0.8341727 | G36: =SUM(G5:G18,G20:G34) -> 0 | H36: =SUM(H5:H18,H20:H34) -> 0 | J36: PERIOD TOTAL WithOut Investment | L36: =SUM(L5:L18,L20:L34) -> 9634.6 | M36: =SUM(M5:M18,M20:M34) -> 0 | N36: =SUM(N5:N18,N20:N34) -> 9634.6 | O36: =SUM(O5:O18,O20:O34) -> 0

Sheet MONTHLY
B1: ="🤯 Average Expenses you do ₹"&TEXT(IFERROR(AVERAGEIF(E5:E24,">0"),0),"##,##0.00") -> 🤯 Average Expenses you do ₹16,885.04 | G1: ="💰 Average Income you do ₹"&TEXT(IFERROR(AVERAGEIF(F5:F24,">0"),0),"##,##0.00") -> 💰 Average Income you do ₹22,749.60 | K1: ="🪙 Average Saving you do ₹"&TEXT(IFERROR(AVERAGEIF(G5:G24,">0"),0),"##,##0.00") -> 🪙 Average Saving you do ₹9,154.46
C3: Time Period | E3: Totals | H3: Ratios | J3: Averages — Actuals
B4: Month | C4: Start Date | D4: End Date | E4: Expenses | F4: Income | G4: Savings | H4: Expense Ratio | I4: Savings Ratio | J4: Expenses | K4: Income | L4: Savings | M4: Remark
B5: =ROW()-4 -> 1 | C5: 45689 | D5: =EOMONTH(C5,0) -> 45716 | E5: =IF($D5="","",IFERROR(SUMIFS(EXPENSES!$D:$D,EXPENSES!$A:$A,">="&$C5,EXPENSES!$A:$A,"<="&$D5),"na")) -> 0 | F5: =IF($D5="","",IFERROR(SUMIFS(INCOME!$C:$C,INCOME!$A:$A,">="&$C5,INCOME!$A:$A,"<="&$D5),"na")) -> 0 | G5: =F5-E5 -> 0 | H5: =IF(F5=0,"na",E5/F5) -> na | I5: =IF(F5=0,"na",G5/F5) -> na | J5: =IFERROR(SUMPRODUCT(EXPENSES!D$4:D$1999),0) -> 84425.18 | K5: =IFERROR(SUMPRODUCT((INCOME!D$4:D$501<>"Expense Money")*(INCOME!C$4:C$501>0)*INCOME!C$4:C$501),0) -> 113748 | L5: =K5-J5 -> 29322.82
B6: =ROW()-4 -> 2 | C6: =EDATE(C5,1) -> 45717 | D6: =EOMONTH(C6,0) -> 45747 | E6: =IF($D6="","",IFERROR(SUMIFS(EXPENSES!$D:$D,EXPENSES!$A:$A,">="&$C6,EXPENSES!$A:$A,"<="&$D6),"na")) -> 9701 | F6: =IF($D6="","",IFERROR(SUMIFS(INCOME!$C:$C,INCOME!$A:$A,">="&$C6,INCOME!$A:$A,"<="&$D6),"na")) -> 21929 | G6: =F6-E6 -> 12228 | H6: =IF(F6=0,"na",E6/F6) -> 0.44238223 | I6: =IF(F6=0,"na",G6/F6) -> 0.55761777 | J6: =IFERROR(SUMPRODUCT(EXPENSES!$D:$D),0) -> 84425.18 | K6: =IF(F6="","",K$5) -> 113748 | L6: =K6-J6 -> 29322.82
B7: =ROW()-4 -> 3 | C7: =EDATE(C6,1) -> 45748 | D7: =EOMONTH(C7,0) -> 45777 | E7: =IF($D7="","",IFERROR(SUMIFS(EXPENSES!$D:$D,EXPENSES!$A:$A,">="&$C7,EXPENSES!$A:$A,"<="&$D7),"na")) -> 29324 | F7: =IF($D7="","",IFERROR(SUMIFS(INCOME!$C:$C,INCOME!$A:$A,">="&$C7,INCOME!$A:$A,"<="&$D7),"na")) -> 22029 | G7: =F7-E7 -> -7295 | H7: =IF(F7=0,"na",E7/F7) -> 1.3311544 | I7: =IF(F7=0,"na",G7/F7) -> -0.33115439 | J7: =IFERROR(SUMPRODUCT(EXPENSES!$D:$D),0) -> 84425.18 | K7: =IF(F7="","",K$5) -> 113748 | L7: =K7-J7 -> 29322.82
B8: =ROW()-4 -> 4 | C8: =EDATE(C7,1) -> 45778 | D8: =EOMONTH(C8,0) -> 45808 | E8: =IF($D8="","",IFERROR(SUMIFS(EXPENSES!$D:$D,EXPENSES!$A:$A,">="&$C8,EXPENSES!$A:$A,"<="&$D8),"na")) -> 15477.58 | F8: =IF($D8="","",IFERROR(SUMIFS(INCOME!$C:$C,INCOME!$A:$A,">="&$C8,INCOME!$A:$A,"<="&$D8),"na")) -> 26029 | G8: =F8-E8 -> 10551.42 | H8: =IF(F8=0,"na",E8/F8) -> 0.5946283 | I8: =IF(F8=0,"na",G8/F8) -> 0.4053717 | J8: =IFERROR(SUMPRODUCT(EXPENSES!$D:$D),0) -> 84425.18 | K8: =IF(F8="","",K$5) -> 113748 | L8: =K8-J8 -> 29322.82
B9: =ROW()-4 -> 5 | C9: =EDATE(C8,1) -> 45809 | D9: =EOMONTH(C9,0) -> 45838 | E9: =IF($D9="","",IFERROR(SUMIFS(EXPENSES!$D:$D,EXPENSES!$A:$A,">="&$C9,EXPENSES!$A:$A,"<="&$D9),"na")) -> 17420.6 | F9: =IF($D9="","",IFERROR(SUMIFS(INCOME!$C:$C,INCOME!$A:$A,">="&$C9,INCOME!$A:$A,"<="&$D9),"na")) -> 24446 | G9: =F9-E9 -> 7025.4 | H9: =IF(F9=0,"na",E9/F9) -> 0.71261556 | I9: =IF(F9=0,"na",G9/F9) -> 0.28738444 | J9: =IFERROR(SUMPRODUCT(EXPENSES!$D:$D),0) -> 84425.18 | K9: =IF(F9="","",K$5) -> 113748 | L9: =K9-J9 -> 29322.82
B10: =ROW()-4 -> 6 | C10: =EDATE(C9,1) -> 45839 | D10: =EOMONTH(C10,0) -> 45869 | E10: =IF($D10="","",IFERROR(SUMIFS(EXPENSES!$D:$D,EXPENSES!$A:$A,">="&$C10,EXPENSES!$A:$A,"<="&$D10),"na")) -> 12502 | F10: =IF($D10="","",IFERROR(SUMIFS(INCOME!$C:$C,INCOME!$A:$A,">="&$C10,INCOME!$A:$A,"<="&$D10),"na")) -> 19315 | G10: =F10-E10 -> 6813 | H10: =IF(F10=0,"na",E10/F10) -> 0.64726896 | I10: =IF(F10=0,"na",G10/F10) -> 0.35273104 | J10: =IFERROR(SUMPRODUCT(EXPENSES!$D:$D),0) -> 84425.18 | K10: =IF(F10="","",K$5) -> 113748 | L10: =K10-J10 -> 29322.82
B11: =ROW()-4 -> 7 | C11: =EDATE(C10,1) -> 45870 | D11: =EOMONTH(C11,0) -> 45900 | E11: =IF($D11="","",IFERROR(SUMIFS(EXPENSES!$D:$D,EXPENSES!$A:$A,">="&$C11,EXPENSES!$A:$A,"<="&$D11),"na")) -> 0 | F11: =IF($D11="","",IFERROR(SUMIFS(INCOME!$C:$C,INCOME!$A:$A,">="&$C11,INCOME!$A:$A,"<="&$D11),"na")) -> 0 | G11: =F11-E11 -> 0 | H11: =IF(F11=0,"na",E11/F11) -> na | I11: =IF(F11=0,"na",G11/F11) -> na | J11: =IFERROR(SUMPRODUCT(EXPENSES!$D:$D),0) -> 84425.18 | K11: =IF(F11="","",K$5) -> 113748 | L11: =K11-J11 -> 29322.82
B12: =ROW()-4 -> 8 | C12: =EDATE(C11,1) -> 45901 | D12: =EOMONTH(C12,0) -> 45930 | E12: =IF($D12="","",IFERROR(SUMIFS(EXPENSES!$D:$D,EXPENSES!$A:$A,">="&$C12,EXPENSES!$A:$A,"<="&$D12),"na")) -> 0 | F12: =IF($D12="","",IFERROR(SUMIFS(INCOME!$C:$C,INCOME!$A:$A,">="&$C12,INCOME!$A:$A,"<="&$D12),"na")) -> 0 | G12: =F12-E12 -> 0 | H12: =IF(F12=0,"na",E12/F12) -> na | I12: =IF(F12=0,"na",G12/F12) -> na | J12: =IFERROR(SUMPRODUCT(EXPENSES!$D:$D),0) -> 84425.18 | K12: =IF(F12="","",K$5) -> 113748 | L12: =K12-J12 -> 29322.82
B13: =ROW()-4 -> 9 | C13: =EDATE(C12,1) -> 45931 | D13: =EOMONTH(C13,0) -> 45961 | E13: =IF($D13="","",IFERROR(SUMIFS(EXPENSES!$D:$D,EXPENSES!$A:$A,">="&$C13,EXPENSES!$A:$A,"<="&$D13),"na")) -> 0 | F13: =IF($D13="","",IFERROR(SUMIFS(INCOME!$C:$C,INCOME!$A:$A,">="&$C13,INCOME!$A:$A,"<="&$D13),"na")) -> 0 | G13: =F13-E13 -> 0 | H13: =IF(F13=0,"na",E13/F13) -> na | I13: =IF(F13=0,"na",G13/F13) -> na | J13: =IFERROR(SUMPRODUCT(EXPENSES!$D:$D),0) -> 84425.18 | K13: =IF(F13="","",K$5) -> 113748 | L13: =K13-J13 -> 29322.82
B14: =ROW()-4 -> 10 | C14: =EDATE(C13,1) -> 45962 | D14: =EOMONTH(C14,0) -> 45991 | E14: =IF($D14="","",IFERROR(SUMIFS(EXPENSES!$D:$D,EXPENSES!$A:$A,">="&$C14,EXPENSES!$A:$A,"<="&$D14),"na")) -> 0 | F14: =IF($D14="","",IFERROR(SUMIFS(INCOME!$C:$C,INCOME!$A:$A,">="&$C14,INCOME!$A:$A,"<="&$D14),"na")) -> 0 | G14: =F14-E14 -> 0 | H14: =IF(F14=0,"na",E14/F14) -> na | I14: =IF(F14=0,"na",G14/F14) -> na | J14: =IFERROR(SUMPRODUCT(EXPENSES!$D:$D),0) -> 84425.18 | K14: =IF(F14="","",K$5) -> 113748 | L14: =K14-J14 -> 29322.82
B15: =ROW()-4 -> 11 | C15: =EDATE(C14,1) -> 45992 | D15: =EOMONTH(C15,0) -> 46022 | E15: =IF($D15="","",IFERROR(SUMIFS(EXPENSES!$D:$D,EXPENSES!$A:$A,">="&$C15,EXPENSES!$A:$A,"<="&$D15),"na")) -> 0 | F15: =IF($D15="","",IFERROR(SUMIFS(INCOME!$C:$C,INCOME!$A:$A,">="&$C15,INCOME!$A:$A,"<="&$D15),"na")) -> 0 | G15: =F15-E15 -> 0 | H15: =IF(F15=0,"na",E15/F15) -> na | I15: =IF(F15=0,"na",G15/F15) -> na | J15: =IFERROR(SUMPRODUCT(EXPENSES!$D:$D),0) -> 84425.18 | K15: =IF(F15="","",K$5) -> 113748 | L15: =K15-J15 -> 29322.82
B16: =ROW()-4 -> 12 | C16: =EDATE(C15,1) -> 46023 | D16: =EOMONTH(C16,0) -> 46053 | E16: =IF($D16="","",IFERROR(SUMIFS(EXPENSES!$D:$D,EXPENSES!$A:$A,">="&$C16,EXPENSES!$A:$A,"<="&$D16),"na")) -> 0 | F16: =IF($D16="","",IFERROR(SUMIFS(INCOME!$C:$C,INCOME!$A:$A,">="&$C16,INCOME!$A:$A,"<="&$D16),"na")) -> 0 | G16: =F16-E16 -> 0 | H16: =IF(F16=0,"na",E16/F16) -> na | I16: =IF(F16=0,"na",G16/F16) -> na | J16: =IFERROR(SUMPRODUCT(EXPENSES!$D:$D),0) -> 84425.18 | K16: =IF(F16="","",K$5) -> 113748 | L16: =K16-J16 -> 29322.82
B17: =ROW()-4 -> 13 | C17: =EDATE(C16,1) -> 46054 | D17: =EOMONTH(C17,0) -> 46081 | E17: =IF($D17="","",IFERROR(SUMIFS(EXPENSES!$D:$D,EXPENSES!$A:$A,">="&$C17,EXPENSES!$A:$A,"<="&$D17),"na")) -> 0 | F17: =IF($D17="","",IFERROR(SUMIFS(INCOME!$C:$C,INCOME!$A:$A,">="&$C17,INCOME!$A:$A,"<="&$D17),"na")) -> 0 | G17: =F17-E17 -> 0 | H17: =IF(F17=0,"na",E17/F17) -> na | I17: =IF(F17=0,"na",G17/F17) -> na | J17: =IFERROR(SUMPRODUCT(EXPENSES!$D:$D),0) -> 84425.18 | K17: =IF(F17="","",K$5) -> 113748 | L17: =K17-J17 -> 29322.82
... B144: =ROW()-4 -> 140 | C144: =EDATE(C143,1) -> 49919 | D144: =EOMONTH(C144,0) -> 49948 | E144: =IF($D144="","",IFERROR(SUMIFS(EXPENSES!$D:$D,EXPENSES!$A:$A,">="&$C144,EXPENSES!$A:$A,"<="&$D144),"na")) -> 0 | F144: =IF($D144="","",IFERROR(SUMIFS(INCOME!$C:$C,INCOME!$A:$A,">="&$C144,INCOME!$A:$A,"<="&$D144),"na")) -> 0 | G144: =F144-E144 -> 0 | H144: =IF(F144=0,"na",E144/F144) -> na | I144: =IF(F144=0,"na",G144/F144) -> na | J144: =IFERROR(SUMPRODUCT(EXPENSES!$D:$D),0) -> 84425.18 | K144: =IF(F144="","",K$5) -> 113748 | L144: =K144-J144 -> 29322.82

Sheet PORTFOLIO
A1: 💼 INVESTMENT PORTFOLIO DASHBOARD — Crypto + Shares + MF
A2: Type | B2: Total Invested ₹ | C2: Total Withdrawn ₹ | D2: Net Invested ₹ | E2: Live Holding ₹ | F2: P & L ₹ | G2: Return % | H2: Status
A3: Crypto | B3: =IFERROR(SUMIFS(INVESTMENTS!F:F,INVESTMENTS!C:C,A3),"") -> 129774.82 | C3: =IFERROR(SUMIFS(INVESTMENTS!K:K,INVESTMENTS!C:C,A3,INVESTMENTS!E:E,"Sell / Redeem"),"0") -> -10362 | D3: =B3-C3 -> 140136.82 | E3: =IFERROR(SUMIFS($E$9:$E$16,$A$9:$A$16,A3),"") -> 95178.614 | F3: =E3-B3-C3 -> -24234.206 | G3: =IFERROR(F3/(B3-C3),0) -> -0.17293247 | H3: =IF(F3>=0,"📈 Profit","📉 Loss") -> 📉 Loss
A4: Shares MF | B4: =IFERROR(SUMIFS(INVESTMENTS!F:F,INVESTMENTS!C:C,A4),"") -> 24010 | C4: =IFERROR(SUMIFS(INVESTMENTS!K:K,INVESTMENTS!C:C,A4,INVESTMENTS!E:E,"Sell / Redeem"),"0") -> 0 | D4: =B4-C4 -> 24010 | E4: =IFERROR(SUMIFS($E$9:$E$16,$A$9:$A$16,A4),"") -> 28684.381 | F4: =E4-B4-C4 -> 4674.3805 | G4: =IFERROR(F4/(B4-C4),0) -> 0.19468474 | H4: =IF(F4>=0,"📈 Profit","📉 Loss") -> 📈 Profit
A5: TOTAL | B5: =SUM(B3:B4) -> 153784.82 | C5: =SUM(C3:C4) -> -10362 | D5: =B5-C5 -> 164146.82 | E5: =SUM(E3:E4) -> 123862.99 | F5: =E5-B5-C5 -> -19559.825 | G5: =IFERROR(F5/(B5-C5),0) -> -0.11916055 | H5: =IF(F5>=0,"📈 Profit","📉 Loss") -> 📉 Loss
A6: ⚠️ Holding Value (yellow) auto-updates
A8: Type | B8: Coin / Share | C8: Units Held | D8: Avg Buy Price ₹ | E8: Current Value ₹ | F8: Total Invested ₹ | G8: P&L ₹ | H8: Return % | I8: Status
A9: =IFERROR(__xludf.DUMMYFUNCTION("SORT( UNIQUE(FILTER(INVESTMENTS!C4:D992,INVESTMENTS!C4:C992<>"""",INVESTMENTS!D4:D992<>"""")), MATCH( INDEX(UNIQUE(FILTER(INVESTMENTS!C4:D992,INVESTMENTS!C4:C992<>"""",INVESTMENTS!D4:D992<>"""")),0,1), {""Crypto"",""Shares MF""}, 0 ), "&"TRUE, 2, TRUE )"),"Crypto") -> Crypto | B9: =IFERROR(__xludf.DUMMYFUNCTION("""COMPUTED_VALUE"""),"Bitcoin (BTC)") -> Bitcoin (BTC) | C9: =IFERROR(SUMIF(INVESTMENTS!D:D,B9,INVESTMENTS!I:I),"Error") -> 0.00871589 | D9: =IFERROR(AVERAGEIF(INVESTMENTS!D:D,B9,INVESTMENTS!J:J),"") -> 1915575.1 | E9: =IFERROR(VLOOKUP(B9,SETTINGS!H:J,3,0)*C9,"0") -> 64368.798 | F9: =IFERROR(SUMIF(INVESTMENTS!D:D,B9,INVESTMENTS!F:F),"") -> 13333.31 | G9: =E9-F9 -> 51035.488 | H9: =IFERROR((E9-F9)/ABS(F9),0) -> 3.8276683 | I9: =IF(G9>=0,"📈 Profit","📉 Loss") -> 📈 Profit
A10: =IFERROR(__xludf.DUMMYFUNCTION("""COMPUTED_VALUE"""),"Crypto") -> Crypto | B10: =IFERROR(__xludf.DUMMYFUNCTION("""COMPUTED_VALUE"""),"Cardano (ADA)") -> Cardano (ADA) | C10: =IFERROR(SUMIF(INVESTMENTS!D:D,B10,INVESTMENTS!I:I),"Error") -> 156.527 | D10: =IFERROR(AVERAGEIF(INVESTMENTS!D:D,B10,INVESTMENTS!J:J),"") -> 36.724444 | E10: =IFERROR(VLOOKUP(B10,SETTINGS!H:J,3,0)*C10,"0") -> 3124.8945 | F10: =IFERROR(SUMIF(INVESTMENTS!D:D,B10,INVESTMENTS!F:F),"") -> 13290.35 | G10: =E10-F10 -> -10165.455 | H10: =IFERROR((E10-F10)/ABS(F10),0) -> -0.76487493 | I10: =IF(G10>=0,"📈 Profit","📉 Loss") -> 📉 Loss
A11: =IFERROR(__xludf.DUMMYFUNCTION("""COMPUTED_VALUE"""),"Crypto") -> Crypto | B11: =IFERROR(__xludf.DUMMYFUNCTION("""COMPUTED_VALUE"""),"Ethereum (ETH)") -> Ethereum (ETH) | C11: =IFERROR(SUMIF(INVESTMENTS!D:D,B11,INVESTMENTS!I:I),"Error") -> 0.09744698 | D11: =IFERROR(AVERAGEIF(INVESTMENTS!D:D,B11,INVESTMENTS!J:J),"") -> 149899.19 | E11: =IFERROR(VLOOKUP(B11,SETTINGS!H:J,3,0)*C11,"0") -> 23579.355 | F11: =IFERROR(SUMIF(INVESTMENTS!D:D,B11,INVESTMENTS!F:F),"") -> 18454.88 | G11: =E11-F11 -> 5124.4751 | H11: =IFERROR((E11-F11)/ABS(F11),0) -> 0.27767588 | I11: =IF(G11>=0,"📈 Profit","📉 Loss") -> 📈 Profit
A12: =IFERROR(__xludf.DUMMYFUNCTION("""COMPUTED_VALUE"""),"Crypto") -> Crypto | B12: =IFERROR(__xludf.DUMMYFUNCTION("""COMPUTED_VALUE"""),"Polygon (MATIC)") -> Polygon (MATIC) | C12: =IFERROR(SUMIF(INVESTMENTS!D:D,B12,INVESTMENTS!I:I),"Error") -> 149.61304 | D12: =IFERROR(AVERAGEIF(INVESTMENTS!D:D,B12,INVESTMENTS!J:J),"") -> 25.665926 | E12: =IFERROR(VLOOKUP(B12,SETTINGS!H:J,3,0)*C12,"0") -> 0 | F12: =IFERROR(SUMIF(INVESTMENTS!D:D,B12,INVESTMENTS!F:F),"") -> 4856.95 | G12: =E12-F12 -> -4856.95 | H12: =IFERROR((E12-F12)/ABS(F12),0) -> -1 | I12: =IF(G12>=0,"📈 Profit","📉 Loss") -> 📉 Loss
A13: =IFERROR(__xludf.DUMMYFUNCTION("""COMPUTED_VALUE"""),"Crypto") -> Crypto | B13: =IFERROR(__xludf.DUMMYFUNCTION("""COMPUTED_VALUE"""),"Solana (SOL)") -> Solana (SOL) | C13: =IFERROR(SUMIF(INVESTMENTS!D:D,B13,INVESTMENTS!I:I),"Error") -> 0.42124869 | D13: =IFERROR(AVERAGEIF(INVESTMENTS!D:D,B13,INVESTMENTS!J:J),"") -> 3780.62 | E13: =IFERROR(VLOOKUP(B13,SETTINGS!H:J,3,0)*C13,"0") -> 4105.5669 | F13: =IFERROR(SUMIF(INVESTMENTS!D:D,B13,INVESTMENTS!F:F),"") -> 1728.33 | G13: =E13-F13 -> 2377.2369 | H13: =IFERROR((E13-F13)/ABS(F13),0) -> 1.3754531 | I13: =IF(G13>=0,"📈 Profit","📉 Loss") -> 📈 Profit
A14: =IFERROR(__xludf.DUMMYFUNCTION("""COMPUTED_VALUE"""),"Shares MF") -> Shares MF | B14: =IFERROR(__xludf.DUMMYFUNCTION("""COMPUTED_VALUE"""),"SBI Savings Fund Direct Plan Growth") -> SBI Savings Fund Direct Plan Growth | C14: =IFERROR(SUMIF(INVESTMENTS!D:D,B14,INVESTMENTS!I:I),"Error") -> 597.218 | D14: =IFERROR(AVERAGEIF(INVESTMENTS!D:D,B14,INVESTMENTS!J:J),"") -> 40.483831 | E14: =IFERROR(VLOOKUP(B14,SETTINGS!H:J,3,0)*C14,"0") -> 28684.381 | F14: =IFERROR(SUMIF(INVESTMENTS!D:D,B14,INVESTMENTS!F:F),"") -> 24010 | G14: =E14-F14 -> 4674.3805 | H14: =IFERROR((E14-F14)/ABS(F14),0) -> 0.19468474 | I14: =IF(G14>=0,"📈 Profit","📉 Loss") -> 📈 Profit
C15: =IFERROR(SUMIF(INVESTMENTS!D:D,B15,INVESTMENTS!I:I),"Error") -> 0 | D15: =IFERROR(AVERAGEIF(INVESTMENTS!D:D,B15,INVESTMENTS!J:J),"") | E15: =IFERROR(VLOOKUP(B15,SETTINGS!H:J,3,0)*C15,"0") -> 0 | F15: =IFERROR(SUMIF(INVESTMENTS!D:D,B15,INVESTMENTS!F:F),"") -> 0 | G15: =E15-F15 -> 0 | H15: =IFERROR((E15-F15)/ABS(F15),0) -> 0 | I15: =IF(G15>=0,"📈 Profit","📉 Loss") -> 📈 Profit
C16: =IFERROR(SUMIF(INVESTMENTS!D:D,B16,INVESTMENTS!I:I),"Error") -> 0 | D16: =IFERROR(AVERAGEIF(INVESTMENTS!D:D,B16,INVESTMENTS!J:J),"") | E16: =IFERROR(VLOOKUP(B16,SETTINGS!H:J,3,0)*C16,"0") -> 0 | F16: =IFERROR(SUMIF(INVESTMENTS!D:D,B16,INVESTMENTS!F:F),"") -> 0 | G16: =E16-F16 -> 0 | H16: =IFERROR((E16-F16)/ABS(F16),0) -> 0 | I16: =IF(G16>=0,"📈 Profit","📉 Loss") -> 📈 Profit
C17: =IFERROR(SUMIF(INVESTMENTS!D:D,B17,INVESTMENTS!I:I),"Error") -> 0 | D17: =IFERROR(AVERAGEIF(INVESTMENTS!D:D,B17,INVESTMENTS!J:J),"") | E17: =IFERROR(multiply(VLOOKUP(B17,SETTINGS!H:J,3,0),C17),"0") -> 0 | F17: =IFERROR(SUMIF(INVESTMENTS!D:D,B17,INVESTMENTS!F:F),"") -> 0 | G17: =E17-F17 -> 0 | H17: =IFERROR((E17-F17)/ABS(F17),0) -> 0 | I17: =IF(G17>=0,"📈 Profit","📉 Loss") -> 📈 Profit
C18: =IFERROR(SUMIF(INVESTMENTS!D:D,B18,INVESTMENTS!I:I),"Error") -> 0 | D18: =IFERROR(AVERAGEIF(INVESTMENTS!D:D,B18,INVESTMENTS!J:J),"") | E18: =IFERROR(multiply(VLOOKUP(B18,SETTINGS!H:J,3,0),C18),"0") -> 0 | F18: =IFERROR(SUMIF(INVESTMENTS!D:D,B18,INVESTMENTS!F:F),"") -> 0 | G18: =E18-F18 -> 0 | H18: =IFERROR((E18-F18)/ABS(F18),0) -> 0 | I18: =IF(G18>=0,"📈 Profit","📉 Loss") -> 📈 Profit
C19: =IFERROR(SUMIF(INVESTMENTS!D:D,B19,INVESTMENTS!I:I),"Error") -> 0 | D19: =IFERROR(AVERAGEIF(INVESTMENTS!D:D,B19,INVESTMENTS!J:J),"") | E19: =IFERROR(multiply(VLOOKUP(B19,SETTINGS!H:J,3,0),C19),"0") -> 0 | F19: =IFERROR(SUMIF(INVESTMENTS!D:D,B19,INVESTMENTS!F:F),"") -> 0 | G19: =E19-F19 -> 0 | H19: =IFERROR((E19-F19)/ABS(F19),0) -> 0 | I19: =IF(G19>=0,"📈 Profit","📉 Loss") -> 📈 Profit
C20: =IFERROR(SUMIF(INVESTMENTS!D:D,B20,INVESTMENTS!I:I),"Error") -> 0 | D20: =IFERROR(AVERAGEIF(INVESTMENTS!D:D,B20,INVESTMENTS!J:J),"") | E20: =IFERROR(multiply(VLOOKUP(B20,SETTINGS!H:J,3,0),C20),"0") -> 0 | F20: =IFERROR(SUMIF(INVESTMENTS!D:D,B20,INVESTMENTS!F:F),"") -> 0 | G20: =E20-F20 -> 0 | H20: =IFERROR((E20-F20)/ABS(F20),0) -> 0 | I20: =IF(G20>=0,"📈 Profit","📉 Loss") -> 📈 Profit
B21: GRAND TOTAL (Crypto + Shares) | E21: =SUM(E9:E20) -> 123862.99 | F21: =SUM(F9:F20) -> 75673.82 | G21: =SUM(G9:G20) -> 48189.175 | H21: =IFERROR(G21/ABS(F21),0) -> 0.63680114

Sheet INVESTMENTS
A1: 📋 ALL INVESTMENT TRANSACTIONS (Crypto + Shares MF)
A2: Auto | B2: Type | C2: Select | D2: Select | E2: Select | F2: Type | G2: Type | H2: Auto | I2: Type | J2: Type | K2: Auto
A3: # | B3: Date | C3: Asset Type | D3: Asset Name | E3: Transaction | F3: Invest Amt | G3: Withdra Amt | H3: Fee Taken | I3: Units / Qty | J3: Price/Unit ₹ | K3: Total Amt ₹
A4: =ROW()-2 -> 2 | B4: 44421 | C4: Crypto | E4: Buy / Invest | F4: -5032 | G4: 5032 | H4: =IF(K4<=0,0,IF(F4>0,F4-K4,G4-K4)) -> 0 | I4: 0 | J4: 0 | K4: =J4*I4 -> 0
A5: =ROW()-2 -> 3 | B5: 44421 | C5: Crypto | D5: Bitcoin (BTC) | E5: Buy / Invest | F5: 5282.62 | G5: 0 | H5: =IF(K5<=0,0,IF(F5>0,F5-K5,G5-K5)) -> 0.002923 | I5: 0.001139 | J5: 4637943 | K5: =J5*I5 -> 5282.6171
A6: =ROW()-2 -> 4 | B6: 44432 | C6: Crypto | D6: Polygon (MATIC) | E6: Buy / Invest | F6: 6941.94 | G6: 0 | H6: =IF(K6<=0,0,IF(F6>0,F6-K6,G6-K6)) -> 0 | I6: 58.83 | J6: 118 | K6: =J6*I6 -> 6941.94
A7: =ROW()-2 -> 5 | B7: 44446 | C7: Crypto | D7: Cardano (ADA) | E7: Buy / Invest | F7: 11667.21 | G7: 0 | H7: =IF(K7<=0,0,IF(F7>0,F7-K7,G7-K7)) -> 0.00424 | I7: 40.231744 | J7: 290 | K7: =J7*I7 -> 11667.206
A8: =ROW()-2 -> 6 | B8: 44459 | C8: Crypto | D8: Polygon (MATIC) | E8: Buy / Invest | F8: 448.99 | G8: 0 | H8: =IF(K8<=0,0,IF(F8>0,F8-K8,G8-K8)) -> -0.0020716896 | I8: 5.0722105 | J8: 88.52 | K8: =J8*I8 -> 448.99207
A9: =ROW()-2 -> 7 | B9: 44491 | C9: Crypto | D9: Ethereum (ETH) | E9: Buy / Invest | F9: 10415.84 | G9: 0 | H9: =IF(K9<=0,0,IF(F9>0,F9-K9,G9-K9)) -> -0.00348 | I9: 0.031924 | J9: 326270 | K9: =J9*I9 -> 10415.843
A10: =ROW()-2 -> 8 | B10: 44535 | C10: Crypto | E10: Buy / Invest | F10: 6988 | G10: 0 | H10: =IF(K10<=0,0,IF(F10>0,F10-K10,G10-K10)) -> 0 | I10: 0 | J10: 0 | K10: =J10*I10 -> 0
A11: =ROW()-2 -> 9 | B11: 44559 | C11: Crypto | E11: Buy / Invest | F11: 63328 | G11: 0 | H11: =IF(K11<=0,0,IF(F11>0,F11-K11,G11-K11)) -> 0 | I11: 0 | J11: 0 | K11: =J11*I11 -> 0
A12: =ROW()-2 -> 10 | B12: 44564 | C12: Crypto | D12: Polygon (MATIC) | E12: Buy / Invest | F12: 660.94 | G12: 0 | H12: =IF(K12<=0,0,IF(F12>0,F12-K12,G12-K12)) -> 0.00428313 | I12: 3.587947 | J12: 184.21 | K12: =J12*I12 -> 660.93572
A13: =ROW()-2 -> 11 | B13: 44777 | C13: Crypto | D13: Cardano (ADA) | E13: Buy / Invest | F13: 1623.14 | G13: 0 | H13: =IF(K13<=0,0,IF(F13>0,F13-K13,G13-K13)) -> 0.001996 | I13: 40.0577 | J13: 40.52 | K13: =J13*I13 -> 1623.138
A14: =ROW()-2 -> 12 | B14: 44913 | C14: Crypto | D14: Ethereum (ETH) | E14: Buy / Invest | F14: 1364.77 | G14: 0 | H14: =IF(K14<=0,0,IF(F14>0,F14-K14,G14-K14)) -> 0.0034612 | I14: 0.014002 | J14: 97469.4 | K14: =J14*I14 -> 1364.7665
A15: =ROW()-2 -> 13 | B15: 44913 | C15: Crypto | D15: Bitcoin (BTC) | E15: Buy / Invest | F15: 1998.97 | G15: 0 | H15: =IF(K15<=0,0,IF(F15>0,F15-K15,G15-K15)) -> -0.002688 | I15: 0.001448 | J15: 1380506 | K15: =J15*I15 -> 1998.9727
A16: =ROW()-2 -> 14 | B16: 44913 | C16: Crypto | D16: Cardano (ADA) | E16: Buy / Invest | F16: 0 | G16: 0 | H16: =IF(K16<=0,0,IF(F16>0,F16-K16,G16-K16)) -> 0 | I16: 32.6527 | J16: 0 | K16: =J16*I16 -> 0
A17: =ROW()-2 -> 15 | B17: 44913 | C17: Crypto | D17: Bitcoin (BTC) | E17: Buy / Invest | F17: 0 | G17: 0 | H17: =IF(K17<=0,0,IF(F17>0,F17-K17,G17-K17)) -> 0 | I17: 0.000332 | J17: 0 | K17: =J17*I17 -> 0
A18: =ROW()-2 -> 16 | B18: 44934 | C18: Crypto | D18: Ethereum (ETH) | E18: Buy / Invest | F18: 744.57 | G18: 0 | H18: =IF(K18<=0,0,IF(F18>0,F18-K18,G18-K18)) -> -0.0005745 | I18: 0.0071583 | J18: 104015 | K18: =J18*I18 -> 744.57057
A19: =ROW()-2 -> 17 | B19: 44934 | C19: Crypto | D19: Bitcoin (BTC) | E19: Buy / Invest | F19: 1003.08 | G19: 0 | H19: =IF(K19<=0,0,IF(F19>0,F19-K19,G19-K19)) -> 0.001662 | I19: 0.000719 | J19: 1395102 | K19: =J19*I19 -> 1003.0783
A20: =ROW()-2 -> 18 | B20: 44943 | C20: Crypto | D20: Polygon (MATIC) | E20: Buy / Invest | F20: 0 | G20: 0 | H20: =IF(K20<=0,0,IF(F20>0,F20-K20,G20-K20)) -> 0 | I20: 27.5 | J20: 0 | K20: =J20*I20 -> 0
A21: =ROW()-2 -> 19 | B21: 44967 | C21: Crypto | D21: Ethereum (ETH) | E21: Buy / Invest | F21: 717.85 | G21: 0 | H21: =IF(K21<=0,0,IF(F21>0,F21-K21,G21-K21)) -> 0.0049304 | I21: 0.0056104 | J21: 127949 | K21: =J21*I21 -> 717.84507
A22: =ROW()-2 -> 20 | B22: 44967 | C22: Crypto | D22: Bitcoin (BTC) | E22: Buy / Invest | F22: 981.59 | G22: 0 | H22: =IF(K22<=0,0,IF(F22>0,F22-K22,G22-K22)) -> 0.0035604 | I22: 0.0005447 | J22: 1802068 | K22: =J22*I22 -> 981.58644
A23: =ROW()-2 -> 21 | B23: 44975 | C23: Crypto | D23: Bitcoin (BTC) | E23: Buy / Invest | F23: 0 | G23: 0 | H23: =IF(K23<=0,0,IF(F23>0,F23-K23,G23-K23)) -> 0 | I23: 0.0026281 | J23: 0 | K23: =J23*I23 -> 0
A24: =ROW()-2 -> 22 | B24: 44988 | C24: Crypto | E24: Buy / Invest | F24: 10000 | G24: 0 | H24: =IF(K24<=0,0,IF(F24>0,F24-K24,G24-K24)) -> 0 | I24: 0 | J24: 0 | K24: =J24*I24 -> 0
A25: =ROW()-2 -> 23 | B25: 44988 | C25: Crypto | E25: Buy / Invest | F25: 2575 | G25: 0 | H25: =IF(K25<=0,0,IF(F25>0,F25-K25,G25-K25)) -> 0 | I25: 0 | J25: 0 | K25: =J25*I25 -> 0
A26: =ROW()-2 -> 24 | B26: 44998 | C26: Crypto | D26: Bitcoin (BTC) | E26: Buy / Invest | F26: 1070.22 | G26: 0 | H26: =IF(K26<=0,0,IF(F26>0,F26-K26,G26-K26)) -> -0.001683 | I26: 0.0005415 | J26: 1976402 | K26: =J26*I26 -> 1070.2217
A27: =ROW()-2 -> 25 | B27: 44998 | C27: Crypto | D27: Ethereum (ETH) | E27: Buy / Invest | F27: 696.34 | G27: 0 | H27: =IF(K27<=0,0,IF(F27>0,F27-K27,G27-K27)) -> -0.000272 | I27: 0.005073 | J27: 137264 | K27: =J27*I27 -> 696.34027
A28: =ROW()-2 -> 26 | B28: 45041 | C28: Crypto | D28: Polygon (MATIC) | E28: Buy / Invest | F28: 0 | G28: 0 | H28: =IF(K28<=0,0,IF(F28>0,F28-K28,G28-K28)) -> 0 | I28: 7.5 | J28: 0 | K28: =J28*I28 -> 0
A29: =ROW()-2 -> 27 | B29: 45079 | C29: Crypto | D29: Ethereum (ETH) | E29: Buy / Invest | F29: 0 | G29: 0 | H29: =IF(K29<=0,0,IF(F29>0,F29-K29,G29-K29)) -> 0 | I29: 0.001253 | J29: 0 | K29: =J29*I29 -> 0
A30: =ROW()-2 -> 28 | B30: 45079 | C30: Crypto | D30: Polygon (MATIC) | E30: Sell / Redeem | F30: -5032 | G30: 5032 | H30: =IF(K30<=0,0,IF(F30>0,F30-K30,G30-K30)) -> 0 | I30: -68 | J30: 74 | K30: =J30*I30 -> -5032
A31: =ROW()-2 -> 29 | B31: 45119 | C31: Crypto | D31: Polygon (MATIC) | E31: Buy / Invest | F31: 0 | G31: 0 | H31: =IF(K31<=0,0,IF(F31>0,F31-K31,G31-K31)) -> 0 | I31: 3.03222 | J31: 0 | K31: =J31*I31 -> 0
A32: =ROW()-2 -> 30 | B32: 45120 | C32: Crypto | D32: Ethereum (ETH) | E32: Buy / Invest | F32: 744.21 | G32: 0 | H32: =IF(K32<=0,0,IF(F32>0,F32-K32,G32-K32)) -> 0.00307 | I32: 0.004841 | J32: 153730 | K32: =J32*I32 -> 744.20693
A33: =ROW()-2 -> 31 | B33: 45120 | C33: Crypto | D33: Polygon (MATIC) | E33: Buy / Invest | F33: 0 | G33: 0 | H33: =IF(K33<=0,0,IF(F33>0,F33-K33,G33-K33)) -> 0 | I33: 69.0798 | J33: 0 | K33: =J33*I33 -> 0
A34: =ROW()-2 -> 32 | B34: 45140 | C34: Crypto | D34: Polygon (MATIC) | E34: Buy / Invest | F34: 0 | G34: 0 | H34: =IF(K34<=0,0,IF(F34>0,F34-K34,G34-K34)) -> 0 | I34: 18.39 | J34: 0 | K34: =J34*I34 -> 0
A35: =ROW()-2 -> 33 | B35: 45200 | C35: Crypto | D35: Bitcoin (BTC) | E35: Buy / Invest | F35: 0 | G35: 0 | H35: =IF(K35<=0,0,IF(F35>0,F35-K35,G35-K35)) -> 0 | I35: 0.00032896 | J35: 0 | K35: =J35*I35 -> 0
A36: =ROW()-2 -> 34 | B36: 45200 | C36: Crypto | D36: Ethereum (ETH) | E36: Buy / Invest | F36: 0 | G36: 0 | H36: =IF(K36<=0,0,IF(F36>0,F36-K36,G36-K36)) -> 0 | I36: 0.0014956 | J36: 0 | K36: =J36*I36 -> 0
A37: =ROW()-2 -> 35 | B37: 45200 | C37: Crypto | D37: Polygon (MATIC) | E37: Buy / Invest | F37: 0 | G37: 0 | H37: =IF(K37<=0,0,IF(F37>0,F37-K37,G37-K37)) -> 0 | I37: 24.81 | J37: 0 | K37: =J37*I37 -> 0
... A71: =ROW()-2 -> 69 | B71: 45395 | C71: Crypto | D71: Ethereum (ETH) | E71: Buy / Invest | F71: 988.16 | G71: 0 | H71: =IF(K71<=0,0,IF(F71>0,F71-K71,G71-K71)) -> -0.004323784 | I71: 0.00317592 | J71: 311142.7 | K71: =J71*I71 -> 988.16432
A72: =ROW()-2 -> 70 | B72: 45396 | C72: Crypto | E72: Buy / Invest | F72: 252 | G72: 0 | H72: =IF(K72<=0,0,IF(F72>0,F72-K72,G72-K72)) -> 0 | I72: 0 | J72: 0 | K72: =J72*I72 -> 0
A73: =ROW()-2 -> 71 | B73: 45398 | C73: Crypto | D73: Polygon (MATIC) | E73: Buy / Invest | F73: 0 | G73: 0 | H73: =IF(K73<=0,0,IF(F73>0,F73-K73,G73-K73)) -> 0 | I73: 46.421 | J73: 0 | K73: =J73*I73 -> 0
...

Sheet SETTINGS
A1: ⚙️ SETTINGS & REFERENCE DATA — Do not change rows 3 onwards unless needed
A2: EXPENSE CATEGORIES | B2: EXPENSE KEYS REFERENCE | C2: INCOME CATEGORIES | D2: ACCOUNT TYPES | F2: TRANSACTION TYPES | G2: Type | H2: CRYPTO ASSETS | I2: Codes | J2: Current Price (INR) | K2: Current Price (USD)
A3: Bills & Utilities | B3: Electricity Bill, Water Bill, Broadband, Mobile Recharge, DTH | C3: Job / Salary | D3: Personal SBI (Saving) | G3: Crypto | H3: Bitcoin (BTC) | I3: Bitcoin | J3: =IFERROR(__xludf.DUMMYFUNCTION("GOOGLEFINANCE(""Currency:USDINR"")*K3"),7385223.728485001) -> 7385223.7 | K3: =IFERROR(__xludf.DUMMYFUNCTION("GOOGLEFINANCE(""BTCUSD"")"),77287.27) -> 77287.27
A4: Childcare & Baby Needs | B4: Diapers, Baby Food, Toys, School Stationery | C4: Side Income | D4: SBI FD | G4: Crypto | H4: Ethereum (ETH) | I4: Ethereum | J4: =IFERROR(__xludf.DUMMYFUNCTION("GOOGLEFINANCE(""Currency:USDINR"")*K4"),241971.1219857) -> 241971.12 | K4: =IFERROR(__xludf.DUMMYFUNCTION("GOOGLEFINANCE(""ETHUSD"")"),2532.2574) -> 2532.2574
A5: Commute | B5: Metro, Bus, Auto-rickshaw, Train, Ola/Uber, Fuel for commute | C5: Expense Money | D5: Kotak Bank | G5: Crypto | H5: Solana (SOL) | I5: Cardano | J5: =IFERROR(__xludf.DUMMYFUNCTION("GOOGLEFINANCE(""Currency:USDINR"")*K5"),9746.183222500002) -> 9746.1832 | K5: =IFERROR(__xludf.DUMMYFUNCTION("VALUE( REGEXEXTRACT( IMPORTDATA(""https://api.coinbase.com/v2/prices/SOL-USD/spot""), """"""amount"""":""""([0-9.]+)"""""" ) ) "),101.995) -> 101.995
A6: Education | B6: School Fees, College Tuition, Coaching Classes, Online Courses | C6: Freelance | D6: Other Bank | G6: Crypto | H6: Cardano (ADA) | I6: Solana | J6: =IFERROR(__xludf.DUMMYFUNCTION("GOOGLEFINANCE(""Currency:USDINR"")*K6"),19.963932837500003) -> 19.963933 | K6: =IFERROR(__xludf.DUMMYFUNCTION("VALUE( REGEXEXTRACT( IMPORTDATA(""https://api.coinbase.com/v2/prices/ADA-USD/spot""), """"""amount"""":""""([0-9.]+)"""""" ) ) "),0.208925) -> 0.208925
A7: Electronics & Gadgets | B7: Mobile Phones, Laptops, Smartwatches, Earphones | C7: Rental Income | G7: Crypto | H7: sBitcoin | I7: sBitcoin | J7: =IFERROR(__xludf.DUMMYFUNCTION("GOOGLEFINANCE(""Currency:USDINR"")*K7"),7385223.728485001) -> 7385223.7 | K7: =IFERROR(__xludf.DUMMYFUNCTION("GOOGLEFINANCE(""BTCUSD"")"),77287.27) -> 77287.27
A8: Entertainment | B8: Movies, Concerts, Video Games, Online Streaming, Events | C8: Interest | G8: Shares & MF | H8: SBI Savings Fund Direct Plan Growth | I8: SBI_SAVI_DIR_1KP6Q5V | J8: =IFERROR(__xludf.DUMMYFUNCTION("GOOGLEFINANCE(I8)"),48.03) -> 48.03
A9: Familly | B9: Parents' Allowance, Kids' School Fees, Household Help Salary | C9: Other | G9: Shares & MF | H9: SBI Gold Direct Plan Growth | I9: SBI_GOLD_DIR_1HYVO74 | J9: =IFERROR(__xludf.DUMMYFUNCTION("GOOGLEFINANCE(I9)"),46.2) -> 46.2
A10: Fitness | B10: Gym Membership, Yoga Classes, Sports Equipment, Protein Powder | G10: Shares & MF | H10: SBI Silver ETF FoF Direct Growth | I10: SBI_SILV_ETF_KWJODO | J10: =IFERROR(__xludf.DUMMYFUNCTION("GOOGLEFINANCE(I10)"),24.17) -> 24.17
A11: Snacks & Quick Bites | B11: Office tea/coffee, Small breaks, Bakery items, Juice, chips, biscuits
A12: Fuel | B12: Petrol, Diesel, CNG, Electric Charging Stations
A13: Gifts | B13: Birthday Gifts, Anniversary Gifts, Festival Gifts, Wedding Gifts, Gifts for Friends
A14: Groceries | B14: Vegetables, Fruits, Dairy, Meat, Frozen Food, Spices, Staples
A15: HouseHold | B15: Furniture, Cleaning Supplies, Kitchen Appliances, Home Decor
A16: Insurance | B16: Life Insurance, Health Insurance, Vehicle Insurance, Term Plans
A17: Investments | B17: Stocks, Mutual Funds, Bonds, Real Estate, Gold, Cryptocurrencies
A18: Loans Given & Taken | B18: Borrowing from Friends, Lending to Family, Interest on Loan
A19: Medical | B19: Medicines, Doctor Consultation, Hospitalization, Surgery
A20: Personal Care | B20: Haircuts, Skincare, Beauty Products, Grooming Kits, Salon
A21: Rent | B21: House Rent, Office Rent, Coworking Space Rental
A22: Repair & Maintenance | B22: Car Servicing, AC Repair, Plumbing, Electrical Work
... A28: Fines & Penalties | B28: Traffic Challan, Late Fee, Overweight Ticket, etc
A29: Other
